<?xml version="1.0" ?>
<!-- =================================================================================== -->
<!-- |    This document was autogenerated by xacro from teleop.urdf.xacro              | -->
<!-- |    EDITING THIS FILE BY HAND IS NOT RECOMMENDED                                 | -->
<!-- =================================================================================== -->
<robot name="teleop" xmlns:xacro="http://ros.org/wiki/xacro">
  <!-- 
  ROS urdf definition of the TELEOP robot by Istituto Italiano di Tecnologia
  
  DO NOT INCLUDE THIS FILE DIRECTLY! USE teleop_robot.urdf.xacro INSTEAD!

  Author: Enrico Mingo

  Inertial matrix has to be in CoM frame (URDF specs)
-->
  <!-- 
  ROS urdf definition of the TELEOP robot by Istituto Italiano di Tecnologia
  
  DO NOT INCLUDE THIS FILE DIRECTLY! USE teleop_robot.urdf.xacro INSTEAD!

  Author: Enrico Mingo Hoffman

  Inertial matrix has to be in CoM frame (URDF specs)

-->
  <link name="base_link"/>
  <joint name="base_joint" type="fixed">
    <parent link="base_link"/>
    <child link="teleop_link0"/>
    <origin rpy="0 0 0" xyz="0 0 0"/>
  </joint>
  <material name="grey">
    <color rgba="0.5 0.5 0.5 1"/>
  </material>
  <material name="red">
    <color rgba="1.0 0.0 0.0 1"/>
  </material>
  <!-- DYNAMICS PARAMETERS NEEDS TO BE CHEKED! -->
  <link name="teleop_link0">
    <inertial>
      <origin rpy="0 0 0" xyz="0.0 0.0 0.0"/>
      <mass value="1.5"/>
      <inertia ixx="0.001" ixy="0.0" ixz="0.0" iyy="0.001" iyz="0.0" izz="0.001"/>
    </inertial>
    <visual>
      <origin rpy="1.57079632679 0 0" xyz="0 0 0"/>
      <geometry name="teleop_link0_visual">
        <mesh filename="package://teleop_urdf/meshes/_teleop_link0.stl" scale="0.001 0.001 0.001"/>
      </geometry>
      <material name="red"/>
    </visual>
    <collision>
      <origin rpy="1.57079632679 0 0" xyz="0 0 0"/>
      <geometry name="teleop_link0_collision">
        <mesh filename="package://teleop_urdf/meshes/simple/_teleop_link0.stl" scale="0.001 0.001 0.001"/>
      </geometry>
    </collision>
  </link>
  <link name="teleop_link1">
    <inertial>
      <origin rpy="0 0 0" xyz="0.0 -0.02 0.05"/>
      <mass value="0.3"/>
      <inertia ixx="0.001" ixy="0.0" ixz="0.0" iyy="0.001" iyz="0.0" izz="0.0008"/>
    </inertial>
    <visual>
      <origin rpy="1.57079632679 0 -1.57079632679" xyz="0 0 0"/>
      <geometry name="teleop_link1_visual">
        <mesh filename="package://teleop_urdf/meshes/_teleop_link1.stl" scale="0.001 0.001 0.001"/>
      </geometry>
      <material name="red"/>
    </visual>
    <collision>
      <origin rpy="1.57079632679 0 -1.57079632679" xyz="0 0 0"/>
      <geometry name="teleop_link1_collision">
        <mesh filename="package://teleop_urdf/meshes/simple/_teleop_link1.stl" scale="0.001 0.001 0.001"/>
      </geometry>
    </collision>
  </link>
  <link name="teleop_link2">
    <inertial>
      <origin rpy="0 0 0" xyz="0.0 0.01 0.18"/>
      <mass value="3.3"/>
      <inertia ixx="0.04" ixy="0.0" ixz="0.0" iyy="0.04" iyz="0.0" izz="0.01"/>
    </inertial>
    <visual>
      <origin rpy="1.57079632679 0 0" xyz="0 0 0"/>
      <geometry name="teleop_link2_visual">
        <mesh filename="package://teleop_urdf/meshes/_teleop_link2.stl" scale="0.001 0.001 0.001"/>
      </geometry>
      <material name="red"/>
    </visual>
    <collision>
      <origin rpy="1.57079632679 0 0" xyz="0 0 0"/>
      <geometry name="teleop_link2_collision">
        <mesh filename="package://teleop_urdf/meshes/simple/_teleop_link2.stl" scale="0.001 0.001 0.001"/>
      </geometry>
    </collision>
  </link>
  <link name="teleop_link3">
    <inertial>
      <origin rpy="0 0 0" xyz="0.0 -0.02 0.05"/>
      <mass value="0.3"/>
      <inertia ixx="0.001" ixy="0.0" ixz="0.0" iyy="0.001" iyz="0.0" izz="0.0008"/>
    </inertial>
    <visual>
      <origin rpy="1.57079632679 0 0" xyz="0 0 0"/>
      <geometry name="teleop_link3_visual">
        <mesh filename="package://teleop_urdf/meshes/_teleop_link3.stl" scale="0.001 0.001 0.001"/>
      </geometry>
      <material name="red"/>
    </visual>
    <collision>
      <origin rpy="1.57079632679 0 0" xyz="0 0 0"/>
      <geometry name="teleop_link3_collision">
        <mesh filename="package://teleop_urdf/meshes/simple/_teleop_link3.stl" scale="0.001 0.001 0.001"/>
      </geometry>
    </collision>
  </link>
  <link name="teleop_link4">
    <inertial>
      <origin rpy="0 0 0" xyz="0.0 0.0 0.1"/>
      <mass value="2.5"/>
      <inertia ixx="0.015" ixy="0.0" ixz="0.0" iyy="0.015" iyz="0.0" izz="0.008"/>
    </inertial>
    <visual>
      <origin rpy="1.57079632679 0 0" xyz="0 0 0"/>
      <geometry name="teleop_link4_visual">
        <mesh filename="package://teleop_urdf/meshes/_teleop_link4.stl" scale="0.001 0.001 0.001"/>
      </geometry>
      <material name="red"/>
    </visual>
    <collision>
      <origin rpy="1.57079632679 0 0" xyz="0 0 0"/>
      <geometry name="teleop_link4_collision">
        <mesh filename="package://teleop_urdf/meshes/simple/_teleop_link4.stl" scale="0.001 0.001 0.001"/>
      </geometry>
    </collision>
  </link>
  <!-- THIS TAKES INTO ACCOUNT THE HAND AS WELL! -->
  <link name="teleop_link5">
    <inertial>
      <origin rpy="0 0 0" xyz="0.0 0.0 0.1"/>
      <mass value="2"/>
      <inertia ixx="0.01" ixy="0.0" ixz="0.0" iyy="0.01" iyz="0.0" izz="0.01"/>
    </inertial>
    <visual>
      <origin rpy="1.57079632679 0 3.14159265359" xyz="0 0 0"/>
      <geometry name="teleop_link5_visual">
        <mesh filename="package://teleop_urdf/meshes/_teleop_link5.stl" scale="0.001 0.001 0.001"/>
      </geometry>
      <material name="red"/>
    </visual>
    <collision>
      <origin rpy="1.57079632679 0 3.14159265359" xyz="0 0 0"/>
      <geometry name="teleop_link5_collision">
        <mesh filename="package://teleop_urdf/meshes/simple/_teleop_link5.stl" scale="0.001 0.001 0.001"/>
      </geometry>
    </collision>
  </link>
  <!-- THIS IN NOT EXACT, TODO: BETTER VALUES HERE -->
  <!--link name ="teleop_link5">
    <inertial>
      <origin xyz="0.0 ${-20*mmTom} ${50*mmTom}" rpy="0 0 0"/>
      <mass value="0.3"/>
      <inertia ixx="${1e+03*mm2Tom2}"  ixy="0.0"  ixz="0.0" iyy="${1e+03*mm2Tom2}" iyz="0.0" izz="${800*mm2Tom2}" />
    </inertial>
    <visual>
      <origin xyz="0 0 0" rpy="${PI_2} 0 ${PI}"/>
      <geometry name="teleop_link5_visual">
        <mesh filename="package://teleop_urdf/meshes/_teleop_link5.stl" scale="0.001 0.001 0.001" />
      </geometry>
      <material name="red"/>
    </visual>
    <collision>
      <origin xyz="0 0 0" rpy="${PI_2} 0 ${PI}"/>
      <geometry name="teleop_link5_collision">
        <mesh filename="package://teleop_urdf/meshes/simple/_teleop_link5.stl" scale="0.001 0.001 0.001" />
      </geometry>             
    </collision>
</link-->
  <joint name="joint1" type="revolute">
    <parent link="teleop_link0"/>
    <child link="teleop_link1"/>
    <origin rpy="0 0 0" xyz="0.0 0 0"/>
    <axis xyz="0 0 1"/>
    <limit effort="55" lower="-1.75" upper="1.75" velocity="11.7"/>
    <dynamics damping="0.03" friction="0"/>
  </joint>
  <joint name="joint2" type="revolute">
    <parent link="teleop_link1"/>
    <child link="teleop_link2"/>
    <origin rpy="0 0 0" xyz="0 0 0.1315"/>
    <axis xyz="0 1 0"/>
    <limit effort="147" lower="-2.15" upper="2.15" velocity="5.2"/>
    <dynamics damping="0.03" friction="0"/>
  </joint>
  <joint name="joint3" type="revolute">
    <parent link="teleop_link2"/>
    <child link="teleop_link3"/>
    <origin rpy="0 0 0" xyz="0 0 0.365"/>
    <axis xyz="0 1 0"/>
    <limit effort="127" lower="-2.15" upper="2.15" velocity="8.1"/>
    <dynamics damping="0.03" friction="0"/>
  </joint>
  <joint name="joint4" type="revolute">
    <parent link="teleop_link3"/>
    <child link="teleop_link4"/>
    <origin rpy="0 0 0" xyz="0 0 0.1"/>
    <axis xyz="0 0 1"/>
    <limit effort="28" lower="-2.79" upper="2.79" velocity="20.4"/>
    <dynamics damping="0.03" friction="0"/>
  </joint>
  <joint name="joint5" type="revolute">
    <parent link="teleop_link4"/>
    <child link="teleop_link5"/>
    <origin rpy="0 0 0" xyz="0 0 0.226"/>
    <axis xyz="0 1 0"/>
    <limit effort="28" lower="-1.83" upper="1.83" velocity="20.4"/>
    <dynamics damping="0.03" friction="0"/>
  </joint>
  <link name="world"/>
  <joint name="world_joint" type="fixed">
    <parent link="world"/>
    <child link="base_link"/>
  </joint>
  <origin rpy="0 0 0" xyz="0 0 0.05"/>
  <link name="TCP"/>
  <joint name="TCP_joint" type="fixed">
    <parent link="teleop_link5"/>
    <child link="TCP"/>
    <origin rpy="0 0 0" xyz="0 0 0.17"/>
  </joint>
</robot>

